2022-08-15T21:20:47.839773+0300 - WARNING Message: С администратором 1079895323 возникли ошибки
2022-08-15T21:20:47.839773+0300 - WARNING Message: С администратором 1079895323 возникли ошибки
2022-08-15T21:22:11.689372+0300 - WARNING Message: С администратором 1079895323 возникли ошибки
2022-08-15T21:22:11.689372+0300 - WARNING Message: С администратором 1079895323 возникли ошибки
2022-08-15T21:22:26.792458+0300 - ERROR Message: An error has been caught in function 'startup', process 'MainProcess' (468), thread 'MainThread' (4060):
Traceback (most recent call last):

  File "C:\python\bots\DatingBot\main.py", line 19, in <module>
    executor.start_polling(dp, on_startup=startup, on_shutdown=shutdown)
    │        │             │              │                    └ <function shutdown at 0x000001730F638940>
    │        │             │              └ <function startup at 0x000001730C3A3E20>
    │        │             └ <aiogram.dispatcher.dispatcher.Dispatcher object at 0x000001730F5EEE30>
    │        └ <function start_polling at 0x000001730F4E7D00>
    └ <module 'aiogram.utils.executor' from 'C:\\python\\bots\\DatingBot\\venv\\lib\\site-packages\\aiogram\\utils\\executor.py'>

  File "C:\python\bots\DatingBot\venv\lib\site-packages\aiogram\utils\executor.py", line 45, in start_polling
    executor.start_polling(
    │        └ <function Executor.start_polling at 0x000001730F50C790>
    └ <aiogram.utils.executor.Executor object at 0x000001730C8FFFD0>

  File "C:\python\bots\DatingBot\venv\lib\site-packages\aiogram\utils\executor.py", line 320, in start_polling
    loop.run_until_complete(self._startup_polling())
    │    │                  │    └ <function Executor._startup_polling at 0x000001730F50CA60>
    │    │                  └ <aiogram.utils.executor.Executor object at 0x000001730C8FFFD0>
    │    └ <function BaseEventLoop.run_until_complete at 0x000001730E5255A0>
    └ <ProactorEventLoop running=True closed=False debug=False>

  File "C:\Users\User\AppData\Local\Programs\Python\Python310\lib\asyncio\base_events.py", line 633, in run_until_complete
    self.run_forever()
    │    └ <function ProactorEventLoop.run_forever at 0x000001730E5CDF30>
    └ <ProactorEventLoop running=True closed=False debug=False>

  File "C:\Users\User\AppData\Local\Programs\Python\Python310\lib\asyncio\windows_events.py", line 321, in run_forever
    super().run_forever()

  File "C:\Users\User\AppData\Local\Programs\Python\Python310\lib\asyncio\base_events.py", line 600, in run_forever
    self._run_once()
    │    └ <function BaseEventLoop._run_once at 0x000001730E527010>
    └ <ProactorEventLoop running=True closed=False debug=False>

  File "C:\Users\User\AppData\Local\Programs\Python\Python310\lib\asyncio\base_events.py", line 1896, in _run_once
    handle._run()
    │      └ <function Handle._run at 0x000001730E4BE950>
    └ <Handle Task.task_wakeup(<Future finished result=None>)>

  File "C:\Users\User\AppData\Local\Programs\Python\Python310\lib\asyncio\events.py", line 80, in _run
    self._context.run(self._callback, *self._args)
    │    │            │    │           │    └ <member '_args' of 'Handle' objects>
    │    │            │    │           └ <Handle Task.task_wakeup(<Future finished result=None>)>
    │    │            │    └ <member '_callback' of 'Handle' objects>
    │    │            └ <Handle Task.task_wakeup(<Future finished result=None>)>
    │    └ <member '_context' of 'Handle' objects>
    └ <Handle Task.task_wakeup(<Future finished result=None>)>

  File "C:\python\bots\DatingBot\venv\lib\site-packages\aiogram\utils\executor.py", line 377, in _startup_polling
    await callback(self.dispatcher)
          │        │    └ <aiogram.dispatcher.dispatcher.Dispatcher object at 0x000001730F5EEE30>
          │        └ <aiogram.utils.executor.Executor object at 0x000001730C8FFFD0>
          └ <function startup at 0x000001730C3A3E20>

> File "C:\python\bots\DatingBot\main.py", line 10, in startup
    await notification()
          └ <function notification at 0x000001730F6388B0>

  File "C:\python\bots\DatingBot\utilits\notification_run_bot.py", line 14, in notification
    ads

NameError: name 'ads' is not defined
2022-08-16T06:19:07.613940+0300 - WARNING Message: Возникла ошибка при установлении геопозиции человека при регистрации

Service timed out
2022-08-16T06:49:11.446246+0300 - WARNING Message: Возникла ошибка при установлении описания профиля человека при регистрации

'city'
2022-08-16T06:49:45.872210+0300 - WARNING Message: Возникла ошибка при установлении описания профиля человека при регистрации

'name_user'
2022-08-16T18:44:11.347530+0300 - WARNING Message: Возникла ошибка в базе данных "register_user"

'cryptography' package is required for sha256_password or caching_sha2_password auth methods
2022-08-16T18:45:22.661278+0300 - WARNING Message: Возникла ошибка в базе данных "register_user"

'cryptography' package is required for sha256_password or caching_sha2_password auth methods
2022-08-16T18:46:01.822323+0300 - WARNING Message: Возникла ошибка в базе данных "register_user"

'cryptography' package is required for sha256_password or caching_sha2_password auth methods
2022-08-17T00:47:36.534221+0300 - WARNING Message: Возникла ошибка при "/profile"

cannot unpack non-iterable coroutine object
2022-08-17T00:47:38.526954+0300 - WARNING Message: Возникла ошибка при "/profile"

cannot unpack non-iterable coroutine object
2022-08-17T00:47:58.872109+0300 - WARNING Message: Возникла ошибка при "/profile"

cannot unpack non-iterable coroutine object
2022-08-17T06:06:45.359615+0300 - WARNING Message: Возникла ошибка в базе данных "register_user"

(1064, "You have an error in your SQL syntax; check the manual that corresponds to your MySQL server version for the right syntax to use near 'None\n            )' at line 11")
2022-08-17T06:06:45.466641+0300 - WARNING Message: Возникла ошибка при "/profile"

(1146, "Table 'dating.register_user' doesn't exist")
2022-08-17T06:07:12.969444+0300 - WARNING Message: Возникла ошибка в базе данных "register_user"

(1064, "You have an error in your SQL syntax; check the manual that corresponds to your MySQL server version for the right syntax to use near 'None\n            )' at line 11")
2022-08-17T06:07:13.109206+0300 - WARNING Message: Возникла ошибка при "/profile"

(1146, "Table 'dating.register_user' doesn't exist")
2022-08-22T01:24:27.232683+0300 - WARNING Message: Возникла ошибка в базе данных "register_user"

(1064, "You have an error in your SQL syntax; check the manual that corresponds to your MySQL server version for the right syntax to use near ')' at line 5")
2022-08-22T01:24:28.860749+0300 - WARNING Message: Возникла ошибка в базе данных "register_user"

(1064, "You have an error in your SQL syntax; check the manual that corresponds to your MySQL server version for the right syntax to use near ')' at line 5")
2022-08-22T01:26:12.134295+0300 - WARNING Message: Возникла ошибка в базе данных "register_user"

(1064, "You have an error in your SQL syntax; check the manual that corresponds to your MySQL server version for the right syntax to use near ')' at line 5")
2022-08-22T01:26:33.628923+0300 - WARNING Message: Возникла ошибка в базе данных "register_user"

(1064, "You have an error in your SQL syntax; check the manual that corresponds to your MySQL server version for the right syntax to use near ')' at line 5")
2022-08-22T01:26:42.734522+0300 - WARNING Message: Возникла ошибка в базе данных "register_user"

(1064, "You have an error in your SQL syntax; check the manual that corresponds to your MySQL server version for the right syntax to use near ')' at line 5")
2022-08-22T01:27:02.274660+0300 - WARNING Message: Возникла ошибка в базе данных "register_user"

(1064, "You have an error in your SQL syntax; check the manual that corresponds to your MySQL server version for the right syntax to use near ')' at line 5")
2022-08-22T01:27:21.640727+0300 - WARNING Message: Возникла ошибка в базе данных "register_user"

(1064, "You have an error in your SQL syntax; check the manual that corresponds to your MySQL server version for the right syntax to use near ')' at line 5")
2022-08-22T01:27:27.396062+0300 - WARNING Message: Возникла ошибка в базе данных "register_user"

(1064, "You have an error in your SQL syntax; check the manual that corresponds to your MySQL server version for the right syntax to use near ')' at line 5")
2022-08-24T15:48:06.822693+0300 - WARNING Message: Возникла ошибка в базе данных "vip (PayPal, Payments.py)"

(1045, "Access denied for user 'root'@'localhost' (using password: NO)")
2022-08-25T07:07:29.874638+0300 - WARNING Message: Возникла ошибка при установлении описания профиля человека при регистрации

Can't use file of type thumbnail as video
2022-08-25T07:08:15.912914+0300 - WARNING Message: Возникла ошибка при установлении геопозиции человека при регистрации

HTTPSConnectionPool(host='nominatim.openstreetmap.org', port=443): Max retries exceeded with url: /search?q=%D0%B0&format=json&limit=1 (Caused by ReadTimeoutError("HTTPSConnectionPool(host='nominatim.openstreetmap.org', port=443): Read timed out. (read timeout=1)"))
2022-08-25T07:17:58.765557+0300 - WARNING Message: Возникла ошибка при "/profile"

There is no photo in the request
